Workbook

Sheet لوحة الترحيب
B1: المملكة العربية السعودية • وزارة التعليم- الإدارة العامة للتعليم بمنطقة الرياض
B2: بوابة لوحة التحكم للمدارس المسندة
B3: العام الدراسي 1448 هـ | الفريق التنفيذي بمحافظة الدوادمي | قطاع السر — بنين
B5: حياكم الله يا أهل الهمة والعطاء
B6: معًا نرتقي، وبهمّتكم نصنع الإنجاز
B7: عضو الفريق التنفيذي
B8: عبدالله خالد العتيبي
B12: 📊 المؤشرات السريعة
B13: ='لوحة التحكم'!A7 -> 6 | D13: ='لوحة التحكم'!C7 -> 79 | F13: ='لوحة التحكم'!E7 -> 13.2 | H13: ='أعمال المشرف'!A7 -> 11
B14: مدارس مسندة | D14: إجمالي المعلمين | F14: متوسط المعلمين | H14: أعمال المتابعة
B16: ✦ بوابة الأقسام — اختر القسم للانتقال مباشرة ✦
B18: 🏠 الصفحة الرئيسية | D18: 📊 لوحة التحكم | F18: 📋 أعمال المشرف | H18: 🏫 بيانات المدارس
B19: نقطة الانطلاق الرئيسية | D19: الإحصائيات العامة | F19: المهام اليومية والأسبوعية | H19: تفاصيل المدارس المسندة
B21: 📈 التحليل والإحصائيات | D21: 📅 خطة الزيارات | F21: 📉 نسب الغياب | H21: 📱 دخول المنصة
B22: إحصائيات متقدمة | D22: الزيارات الأسبوعية | F22: متابعة الانضباط المدرسي | H22: تقرير دخول مدرستي
B24: 📝 التقرير الأسبوعي | D24: 📈 الملخص الشهري | F24: 📅 توزيع الأسابيع | H24: 📖 التعليمات
B25: الأسبوع الثالث · التشخيصية | D25: حسب الشهر والأسبوع | F25: أسابيع الفصل الأول 1448 | H25: دليل الاستخدام
B27: ◆ 🏫 المدارس المسندة (6 مدارس) — اضغط على اسم المدرسة للانتقال إلى بياناتها ◆
B28: 1. الارطاوي الثانوية | E28: 2. الارطاوي المتوسطة | H28: 3. الملك عبدالعزيز الابتدائية بالارطاوي
B29: 4. وثيلان وعشيران الثانوية | E29: 5. وثيلان وعشيران المتوسطة | H29: 6. وثيلان وعشيران الابتدائية
B31: عبدالله خالد العتيبي | الفريق التنفيذي بمحافظة الدوادمي — قطاع السر | وزارة التعليم | العام الدراسي 1448هـ
B32: ◆ هذه البوابة مصممة لتسهيل المتابعة والإشراف على المدارس المسندة — جميع البيانات تتحدث تلقائياً ◆

Sheet تحليل وإحصائيات
A1: وزارة التعليم | المملكة العربية السعودية
A2: تحليل وإحصائيات — المدارس المسندة لعضو الفريق التنفيذي بمحافظة الدوادمي بقطاع السر | G2: 🏠 العودة للصفحة الرئيسية
A3: عضو الفريق التنفيذي: عبدالله خالد العتيبي | العام الدراسي 1448هـ
A5: إحصائيات عدد المعلمين
A6: العدد الإجمالي للمعلمين | B6: =SUM('بيانات المدارس'!H5:H17) -> 79
A7: متوسط عدد المعلمين | B7: =IFERROR(ROUND(AVERAGE('بيانات المدارس'!H5:H17),2),0) -> 13.17
A8: الوسيط (Median) | B8: =IFERROR(ROUND(MEDIAN('بيانات المدارس'!H5:H17),2),0) -> 13.5
A9: أقل عدد معلمين | B9: =IFERROR(MIN('بيانات المدارس'!H5:H17),0) -> 8
A10: أعلى عدد معلمين | B10: =IFERROR(MAX('بيانات المدارس'!H5:H17),0) -> 18
A11: الانحراف المعياري | B11: =IFERROR(ROUND(STDEV('بيانات المدارس'!H5:H17),2),0) -> 3.71
A13: توزيع النتائج
A14: النتيجة | B14: العدد | C14: النسبة | D14: ملاحظة
A15: ممتاز | B15: =COUNTIF('بيانات المدارس'!N5:N17,A15) -> 0 | C15: =IFERROR(ROUND(B15/COUNTA('بيانات المدارس'!B5:B17)*100,1),0) -> 0 | D15: مستوى متميز
A16: جيد جداً | B16: =COUNTIF('بيانات المدارس'!N5:N17,A16) -> 0 | C16: =IFERROR(ROUND(B16/COUNTA('بيانات المدارس'!B5:B17)*100,1),0) -> 0 | D16: مستوى مرتفع
A17: جيد | B17: =COUNTIF('بيانات المدارس'!N5:N17,A17) -> 0 | C17: =IFERROR(ROUND(B17/COUNTA('بيانات المدارس'!B5:B17)*100,1),0) -> 0 | D17: مستوى مقبول
A18: مقبول | B18: =COUNTIF('بيانات المدارس'!N5:N17,A18) -> 0 | C18: =IFERROR(ROUND(B18/COUNTA('بيانات المدارس'!B5:B17)*100,1),0) -> 0 | D18: يحتاج تحسين
A19: ضعيف | B19: =COUNTIF('بيانات المدارس'!N5:N17,A19) -> 0 | C19: =IFERROR(ROUND(B19/COUNTA('بيانات المدارس'!B5:B17)*100,1),0) -> 0 | D19: يحتاج دعم عاجل
A21: متابعة الأعمدة المعبأة (عدد المدارس التي تم تعبئة البيانات فيها)
A22: العمود | B22: عدد المدارس المعبأة | C22: النسبة % | D22: ملاحظة
A23: موجه صحي مكلف | B23: =COUNTA('بيانات المدارس'!R5:R17) -> 6 | C23: =IFERROR(ROUND(B23/COUNTA('بيانات المدارس'!B5:B17)*100,1),0) -> 100 | D23: وجود موجه صحي مكلف
A24: موجه طلابي | B24: =COUNTA('بيانات المدارس'!S5:S17) -> 6 | C24: =IFERROR(ROUND(B24/COUNTA('بيانات المدارس'!B5:B17)*100,1),0) -> 100 | D24: وجود موجه طلابي
A25: دراسة نتائج الاختبارات المركزية | B25: =COUNTA('بيانات المدارس'!T5:T17) -> 6 | C25: =IFERROR(ROUND(B25/COUNTA('بيانات المدارس'!B5:B17)*100,1),0) -> 100 | D25: دراسة نتائج الاختبارات
A26: بناء خطة المدرسة للمدير | B26: =COUNTA('بيانات المدارس'!U5:U17) -> 6 | C26: =IFERROR(ROUND(B26/COUNTA('بيانات المدارس'!B5:B17)*100,1),0) -> 100 | D26: خطة المدرسة
A27: أعمال مدير المدرسة والتكليفات | B27: =COUNTA('بيانات المدارس'!V5:V17) -> 6 | C27: =IFERROR(ROUND(B27/COUNTA('بيانات المدارس'!B5:B17)*100,1),0) -> 100 | D27: أعمال مدير المدرسة
A28: دخول المعلمين | B28: =COUNTA('بيانات المدارس'!J5:J17) -> 9 | C28: =IFERROR(ROUND(B28/COUNTA('بيانات المدارس'!B5:B17)*100,1),0) -> 150 | D28: حالة دخول المعلمين للمنصة
A29: دخول الطلاب المنصة | B29: =COUNTA('بيانات المدارس'!L5:L17) -> 6 | C29: =IFERROR(ROUND(B29/COUNTA('بيانات المدارس'!B5:B17)*100,1),0) -> 100 | D29: حالة دخول الطلاب للمنصة
A31: ملاحظات:
A32: • جميع القيم والصيغ تتحدث تلقائياً عند إضافة أو تعديل بيانات في ورقة 'بيانات المدارس'.
A33: • استخدم الفلتر في ورقة البيانات لفرز وترتيب حسب أي عمود.
A34: • الألوان في عمود النتيجة (N) تظهر تلقائياً حسب القيمة (ممتاز / جيد جداً / جيد / مقبول / ضعيف).
A35: • قسم 'متابعة الأعمدة المعبأة' يعرض عدد المدارس التي تم تعبئة كل عمود فيها ونسبتها.
A36: • عمود عدد المعلمين = H ، وعمود النتيجة = N . تأكد من إدخال القيم الصحيحة ليظهر التحليل بدقة.
A38: عضو الفريق التنفيذي: عبدالله خالد العتيبي | الفريق التنفيذي بقطاع السر | وزارة التعليم

Sheet الصفحة الرئيسية
A1: المملكة العربية السعودية - وزارة التعليم
A2: الفريق التنفيذي بمحافظة الدوادمي - قطاع السر - بنين
A5: لوحة التحكم للمدارس المسندة
A6: العام الدراسي 1448هـ
B8: مرحباً بك
B9: عضو الفريق التنفيذي
B10: عبدالله خالد العتيبي
B11: قطاع السر بنين
B13: ملخص سريع
B14: ='لوحة التحكم'!A7 -> 6 | D14: ='لوحة التحكم'!C7 -> 79 | F14: ='لوحة التحكم'!E7 -> 13.2 | H14: ='أعمال المشرف'!A7 -> 11
B15: مدارس مسندة | D15: إجمالي المعلمين | F15: متوسط المعلمين | H15: أعمال المتابعة
B17: أقسام اللوحة — اختر القسم للانتقال (يشمل التقارير والملخص الشهري)
B18: 📊 لوحة التحكم | D18: 📋 أعمال المشرف | F18: 🏫 بيانات المدارس | H18: 📈 التحليل
B19: الإحصائيات العامة | D19: المهام اليومية والأسبوعية | F19: تفاصيل المدارس المسندة | H19: إحصائيات متقدمة
B20: 📖 التعليمات | D20: 📅 خطة الزيارات | F20: 📉 نسب الغياب | H20: 📱 دخول المنصة
B21: دليل الاستخدام | D21: الزيارات الأسبوعية للمدارس | F21: متابعة الانضباط المدرسي + رسوم | H21: تقرير أسبوعي للمعلمين والطلاب
B22: 📝 التقرير الأسبوعي | D22: 📈 الملخص الشهري للزيارات | F22: التقارير والمتابعة | H22: 📅 توزيع الأسابيع
B23: الأسبوع الثالث · الاختبارات التشخيصية | D23: حسب الشهر والأسبوع والمدرسة | F23: التقرير الأسبوعي + ملخص الزيارات الشهري | H23: أسابيع الفصل الدراسي الأول 1448
B25: 🏫 المدارس المسندة (6 مدارس)
B26: 1. الارطاوي الثانوية | F26: 2. الارطاوي المتوسطة
B27: 3. الملك عبدالعزيز الابتدائية بالارطاوي | F27: 4. وثيلان وعشيران الثانوية
B28: 5. وثيلان وعشيران المتوسطة | F28: 6. وثيلان وعشيران الابتدائية
B29: اضغط على اسم المدرسة للانتقال إلى بيانات المدارس
B30: 📅 توزيع أسابيع الفصل الدراسي الأول 1448هـ — اضغط هنا للاطلاع على التفاصيل الكاملة (19 أسبوعاً)
A31: عضو الفريق التنفيذي: عبدالله خالد العتيبي | الفريق التنفيذي بقطاع الدوادمي بقطاع السر | وزارة التعليم | العام الدراسي 1448هـ

Sheet توزيع الأسابيع
A1: الإدارة العامة للتعليم بمنطقة الرياض | الشؤون التعليمية - إدارة أداء التعليم
A2: الفريق التنفيذي للممارسات الإشرافية بمحافظة الدوادمي — قطاع السر
A3: توزيع الأسابيع الدراسية للفصل الدراسي الأول للعام الدراسي 1448 هـ
J4: 🏠 العودة للصفحة الرئيسية
B5: الأسبوع | C5: التاريخ | D5: ملاحظات | F5: الأسبوع | G5: التاريخ | H5: ملاحظات
B6: 1. الأول | C6: 3/10 – 3/14 | D6: — | F6: 11. الحادي عشر | G6: 5/21 – 5/25 | H6: —
B7: 2. الثاني | C7: 3/17 – 3/21 | D7: — | F7: 12. الثاني عشر | G7: 5/28 – 6/2 | H7: —
B8: 3. الثالث | C8: 3/24 – 3/28 | D8: — | F8: 13. الثالث عشر | G8: 6/5 – 6/9 | H8: بداية إجازة الخريف بنهاية دوام الخميس1448/6/9
B9: 4. الرابع | C9: 4/2 – 4/6 | D9: — | F9: 14. الرابع عشر | G9: 6/19 – 6/23 | H9: إجازة إضافية الأحد
B10: 5. الخامس | C10: 4/9 – 4/13 | D10: إجازة اليوم الوطني الأربعاء والخميس | F10: 15. الخامس عشر | G10: 6/26 – 7/1 | H10: —
B11: 6. السادس | C11: 4/16 – 4/20 | F11: 16. السادس عشر | G11: 7/4 – 7/8 | H11: —
B12: 7. السابع | C12: 4/23 – 4/27 | D12: — | F12: 17. السابع عشر | G12: 7/11 – 7/15 | H12: —
B13: 8. الثامن | C13: 4/30 – 5/4 | D13: — | F13: 18. الثامن عشر | G13: 7/18 – 7/22 | H13: —
B14: 9. التاسع | C14: 5/7 – 5/11 | D14: — | F14: 19. التاسع عشر | G14: 7/25 – 7/29 | H14: اختبارات نهاية الفترة + إجازة إضافية
B15: 10. العاشر | C15: 5/14 – 5/18 | D15: إجازة إضافية الأحد
B17: بداية إجازة الخريف بنهاية دوام يوم الخميس 1448/6/9 هـ
B18: اختبارات نهاية الفترة الدراسية الأولى (الفصل الدراسي الأول) في الأسبوع التاسع عشر | إجازة إضافية في نهاية الأسبوع
B20: ملاحظة: | C20: الخلايا البرتقالية تشير إلى وجود إجازات خلال الأسبوع. التواريخ بالتقويم الهجري 1448 هـ.
B22: عضو الفريق التنفيذي: عبدالله خالد العتيبي | الفريق التنفيذي بقطاع السر | وزارة التعليم | العام الدراسي 1448هـ

Sheet لوحة التحكم
A1: وزارة التعليم | المملكة العربية السعودية
A2: الفريق التنفيذي بمحافظة الدوادمي - بقطاع السر | J2: 🏠 العودة للصفحة الرئيسية
A3: لوحة التحكم للمدارس المسندة لعضو الفريق التنفيذي | العام الدراسي 1448هـ
A4: عضو الفريق التنفيذي: عبدالله خالد العتيبي
A6: إجمالي المدارس | C6: إجمالي المعلمين | E6: متوسط المعلمين | G6: أعلى عدد معلمين
A7: =COUNTA('بيانات المدارس'!B5:B17) -> 6 | C7: =SUM('بيانات المدارس'!H5:H17) -> 79 | E7: =IFERROR(ROUND(AVERAGE('بيانات المدارس'!H5:H17),1),0) -> 13.2 | G7: =IFERROR(MAX('بيانات المدارس'!H5:H17),0) -> 18
A9: توزيع نتائج المدارس | E9: أعلى المدارس بعدد المعلمين
A10: النتيجة | B10: العدد | C10: النسبة % | E10: المدرسة | F10: عدد المعلمين | G10: النتيجة | H10: الترتيب
A11: ممتاز | B11: =COUNTIF('بيانات المدارس'!N5:N17,A11) -> 0 | C11: =IFERROR(ROUND(B11/$A$7*100,1),0) -> 0 | E11: {=IFERROR(INDEX('بيانات المدارس'!B5:B17,MATCH(LARGE('بيانات المدارس'!H5:H17,1),'بيانات المدارس'!H5:H17,0)),"")} -> وثيلان وعشيران الابتدائية | F11: =IFERROR(LARGE('بيانات المدارس'!H5:H17,1),"") -> 18 | G11: {=IFERROR(INDEX('بيانات المدارس'!N5:N17,MATCH(LARGE('بيانات المدارس'!H5:H17,1),'بيانات المدارس'!H5:H17,0)),"")} -> لم تصدر | H11: 1
A12: جيد جداً | B12: =COUNTIF('بيانات المدارس'!N5:N17,A12) -> 0 | C12: =IFERROR(ROUND(B12/$A$7*100,1),0) -> 0 | E12: {=IFERROR(INDEX('بيانات المدارس'!B5:B17,MATCH(LARGE('بيانات المدارس'!H5:H17,2),'بيانات المدارس'!H5:H17,0)),"")} -> وثيلان وعشيران الثانوية | F12: =IFERROR(LARGE('بيانات المدارس'!H5:H17,2),"") -> 16 | G12: {=IFERROR(INDEX('بيانات المدارس'!N5:N17,MATCH(LARGE('بيانات المدارس'!H5:H17,2),'بيانات المدارس'!H5:H17,0)),"")} -> لم تصدر | H12: 2
A13: جيد | B13: =COUNTIF('بيانات المدارس'!N5:N17,A13) -> 0 | C13: =IFERROR(ROUND(B13/$A$7*100,1),0) -> 0 | E13: {=IFERROR(INDEX('بيانات المدارس'!B5:B17,MATCH(LARGE('بيانات المدارس'!H5:H17,3),'بيانات المدارس'!H5:H17,0)),"")} -> وثيلان وعشيران المتوسطة | F13: =IFERROR(LARGE('بيانات المدارس'!H5:H17,3),"") -> 14 | G13: {=IFERROR(INDEX('بيانات المدارس'!N5:N17,MATCH(LARGE('بيانات المدارس'!H5:H17,3),'بيانات المدارس'!H5:H17,0)),"")} -> لم تصدر | H13: 3
A14: مقبول | B14: =COUNTIF('بيانات المدارس'!N5:N17,A14) -> 0 | C14: =IFERROR(ROUND(B14/$A$7*100,1),0) -> 0
A15: ضعيف | B15: =COUNTIF('بيانات المدارس'!N5:N17,A15) -> 0 | C15: =IFERROR(ROUND(B15/$A$7*100,1),0) -> 0
A18: عضو الفريق التنفيذي: عبدالله خالد العتيبي | الفريق التنفيذي بمحافظة الدوادمي بقطاع السر | وزارة التعليم

Sheet أعمال المشرف
A1: وزارة التعليم | المملكة العربية السعودية
A2: الفريق التنفيذي بمحافظة الدوادمي - بقطاع السر | L2: 🏠 العودة للصفحة الرئيسية
A3: لوحة أعمال المشرف | العام الدراسي 1448هـ
A4: عضو الفريق التنفيذي: عبدالله خالد العتيبي
A6: إجمالي الأعمال | C6: الأعمال المنجزة | E6: قيد التنفيذ | G6: لم تُنجز | I6: نسبة الإنجاز %
A7: =COUNTA(C12:C16)+COUNTA(C20:C24)+COUNTA(C28) -> 11 | C7: =COUNTIF(C12:C16,"منجز")+COUNTIF(C20:C24,"منجز")+COUNTIF(C28,"منجز") -> 8 | E7: =COUNTIF(C12:C16,"قيد التنفيذ")+COUNTIF(C20:C24,"قيد التنفيذ")+COUNTIF(C28,"قيد التنفيذ") -> 1 | G7: =COUNTIF(C12:C16,"لم تُنجز")+COUNTIF(C20:C24,"لم تُنجز")+COUNTIF(C28,"لم تُنجز") -> 2 | I7: =IFERROR(ROUND(C7/A7*100,1),0) -> 72.7
C8: لم ينجز
A9: 📋 الأعمال اليومية | G9: إحصائيات الأعمال اليومية
A11: م | B11: المهمة | C11: الحالة | D11: تاريخ آخر إنجاز | E11: ملاحظات | G11: المنجز | H11: قيد التنفيذ | I11: لم تُنجز | J11: النسبة %
A12: 1 | B12: تثبيت الغياب | C12: منجز | E12: يومياً الرصد قبل الساعة 8 ص | G12: =COUNTIF(C12:C16,"منجز") -> 4 | H12: =COUNTIF(C12:C16,"قيد التنفيذ") -> 1 | I12: =COUNTIF(C12:C16,"لم تُنجز") -> 0 | J12: =IFERROR(ROUND(G12/5*100,1),0) -> 80
A13: 2 | B13: متابعة دخول المعلمين منصة مدرستي | C13: منجز | G13: من 5 أعمال يومية
A14: 3 | B14: متابعة دخول الطلاب منصة مدرستي | C14: قيد التنفيذ | E14: نسب الدخول متدنية تحتاج متابعة لجميع المدارس
A15: 4 | B15: متابعة حضوري | C15: منجز | E15: https://hather-ui.moe.gov.sa/landing?returnUrl=%2Fdashboard
A16: 5 | B16: متابعة فارس | C16: منجز | E16: https://sshr.moe.gov.sa/OA_HTML/AppsLocalLogin.jsp
A17: 6 | B17: متابعة اللوحة الرقمية للمدرسة | C17: لم تنجز | E17: لم تفعل بعد من قبل الإدارة
A18: 📅 الأعمال الأسبوعية | G18: إحصائيات الأعمال الأسبوعية
A19: م | B19: المهمة | C19: الحالة | D19: تاريخ آخر إنجاز | E19: ملاحظات | G19: المنجز | H19: قيد التنفيذ | I19: لم تُنجز | J19: النسبة %
A20: 1 | B20: إدخال خطة الزيارات للمدارس المسندة (رابط الفريق) | C20: منجز | D20: السبت من كل اسبوع | E20: https://docs.google.com/forms/d/1INvJ0EjqH3vEnfn5l9bB2kCzMGEXRaizlKIkpBBefiU/viewform?edit_requested=true | G20: =COUNTIF(C20:C24,"منجز") -> 3 | H20: =COUNTIF(C20:C24,"قيد التنفيذ") -> 0 | I20: =COUNTIF(C20:C24,"لم تُنجز") -> 2 | J20: =IFERROR(ROUND(G20/5*100,1),0) -> 60
A21: 2 | B21: تقارير الزيارة | C21: منجز | D21: نهاية كل اسبوع | G21: من 5 أعمال أسبوعية
A22: 3 | B22: تقرير متابعة نسب غياب الطلاب والانضباط المدرسي | C22: منجز
A23: 4 | B23: تقرير التوجيه الطلابي (اللوحة الرقمية) | C23: لم تُنجز
A24: 5 | B24: ما نُفذ من خطة التحسين (استمارة رقم 2) | C24: لم تُنجز
A26: 🗓️ الأعمال الشهرية | G26: إحصائيات الأعمال الشهرية
A27: م | B27: المهمة | C27: الحالة | D27: تاريخ آخر إنجاز | E27: ملاحظات | G27: المنجز | H27: قيد التنفيذ | I27: لم تُنجز | J27: النسبة %
A28: 1 | B28: تقرير حضوري | C28: منجز | E28: نهاية كل شهر | G28: =COUNTIF(C28,"منجز") -> 1 | H28: =COUNTIF(C28,"قيد التنفيذ") -> 0 | I28: =COUNTIF(C28,"لم تُنجز") -> 0 | J28: =IFERROR(ROUND(G28/1*100,1),0) -> 100
G29: من 1 عمل شهري
A31: 📊 ملخص الإنجاز حسب الفئة
A32: الفئة | B32: عدد الأعمال | C32: منجز | D32: قيد التنفيذ | E32: لم تُنجز | F32: نسبة الإنجاز %
A33: أعمال يومية | B33: 5 | C33: =G12 -> 4 | D33: =H12 -> 1 | E33: =I12 -> 0 | F33: =J12 -> 80
A34: أعمال أسبوعية | B34: 5 | C34: =G20 -> 3 | D34: =H20 -> 0 | E34: =I20 -> 2 | F34: =J20 -> 60
A35: أعمال شهرية | B35: 1 | C35: =G28 -> 1 | D35: =H28 -> 0 | E35: =I28 -> 0 | F35: =J28 -> 100
A36: الإجمالي | B36: =B33+B34+B35 -> 11 | C36: =C33+C34+C35 -> 8 | D36: =D33+D34+D35 -> 1 | E36: =E33+E34+E35 -> 2 | F36: =IFERROR(ROUND(C36/B36*100,1),0) -> 72.7
A38: تعليمات الاستخدام
A39: • غيّر حالة كل مهمة من القائمة المنسدلة في عمود «الحالة»: (منجز / قيد التنفيذ / لم تُنجز) • أدخل تاريخ آخر إنجاز في عمود «تاريخ آخر إنجاز» (مثال: 1448/01/15) • أضف ملاحظاتك في عمود «ملاحظات» • جميع الإحصائيات ونسب الإنجاز تتحدث تلقائياً عند تغيير الحالات • الألوان تتغير تلقائياً: أخضر = منجز | أصفر = قيد التنفيذ | أحمر = لم تُنجز
A43: عضو الفريق التنفيذي : عبدالله خالد العتيبي | الفريق التنفيذي بمحافظة الدوادمي - بقطاع السر | وزارة التعليم

Sheet بيانات المدارس
A1: وزارة التعليم | المملكة العربية السعودية
A2: الفريق التنفيذي بمحافظة الدوادمي - بقطاع السر — لوحة التحكم للمدارس المسندة | العام الدراسي 1448هـ | W2: 🏠 العودة للصفحة الرئيسية
A3: عضو الفريق التنفيذي: عبدالله خالد العتيبي
A4: م | B4: اسم المدرسة | C4: الرقم الوزاري | D4: اسم مدير المدرسة | E4: رقم جوال المدير | F4: اسم وكيل المدرسة | G4: رقم جوال الوكيل | H4: عدد المعلمين | I4: توفر التخصصات | J4: دخول المعلمين | K4: عدد الطلاب | L4: دخول الطلاب المنصة | M4: القدرات والتحصيلي | N4: نتيجة تقرير المدرسة العامة 2026 | O4: نواتج التعلم | P4: تحليل بطافة نافس | Q4: التقرير الخارجي | R4: موجه صحي مكلف | S4: موجه طلابي | T4: دراسة نتائج الاختبارات المركزية | U4: بناء خطة المدرسة للمدير | V4: أعمال مدير المدرسة والتكليفات
A5: 1 | B5: الارطاوي الثانوية | C5: 3917285 | D5: فارس خلف الصبيحي | E5: 549037937 | F5: مفلح جازي المطيري | G5: 533871222 | H5: 8 | I5: نعم | J5: تم | K5: 50 | L5: يحتاج متابعة | M5: تم التحليل | N5: لم تصدر | P5: -------- | Q5: لم يصدر | R5: يوجد | S5: يوجد | T5: غير مشمول | U5: نعم | V5: نعم
A6: 2 | B6: الارطاوي المتوسطة | C6: 17229 | D6: فارس خلف الصبيحي | E6: 549037937 | F6: مفلح جازي المطيري | G6: 53871222 | H6: 10 | I6: عجز بدنية وفنية | J6: تم | K6: 55 | L6: يحتاج متابعة | M6: ----- | N6: لم تصدر | P6: نعم | Q6: لم يصدر | R6: يوجد | S6: يوجد | T6: تم | U6: نعم | V6: نعم
A7: 3 | B7: الملك عبدالعزيز الابتدائية بالارطاوي | C7: 17108 | D7: يوسف بدر المطيري | E7: 509669902 | F7: فلاح محمد المطيري | G7: 595553571 | H7: 13 | I7: نعم | J7: باقي 1 | K7: 96 | L7: يحتاج متابعة | M7: ----- | N7: لم تصدر | P7: لم تصدر البطاقة | Q7: لم يصدر | R7: يوجد | S7: يوجد | T7: تم | U7: نعم | V7: نعم
A8: 4 | B8: وثيلان وعشيران الثانوية | C8: 3917315 | D8: بدر راشد المطيري | E8: 503809808 | F8: عمر مقحم المطيري | G8: 537922224 | H8: 16 | I8: نعم | J8: نعم | K8: 97 | L8: يحتاج متابعة | M8: تم التحليل | N8: لم تصدر | P8: -------- | Q8: لم يصدر | R8: يوجد | S8: يوجد | T8: غير مشمول | U8: نعم | V8: نعم
A9: 5 | B9: وثيلان وعشيران المتوسطة | C9: 17276 | D9: فيحان سعد المطيري | E9: 505174491 | F9: عبدالكريم عبدالله الصبيحي | G9: 557731773 | H9: 14 | I9: عجز بدنية وفنية | J9: نعم | K9: 50 | L9: يحتاج متابعة | M9: ------ | N9: لم تصدر | P9: نعم | Q9: لم يصدر | R9: يوجد | S9: يوجد | T9: تم | U9: نعم | V9: نعم
A10: 6 | B10: وثيلان وعشيران الابتدائية | C10: 17217 | D10: فيصل محمد المطيري | E10: 591511545 | F10: خالد محمد العبدالله | G10: 506141890 | H10: 18 | I10: نعم | J10: نعم | K10: 122 | L10: يحتاج متابعة | M10: ------ | N10: لم تصدر | P10: نعم | Q10: لم يصدر | R10: يوجد | S10: يوجد | T10: تم | U10: نعم | V10: نعم
A11: 7
A12: 8 | H12: مدارس التحسين
A13: 9 | I13: الملك عبدالعزيز | J13: الارطاوي المتوسطة
A14: 10 | H14: رفع خطة التدخل | I14: نعم | J14: نعم
A15: 11 | H15: تنفيذ الاختبارا لتشخيصي | I15: نعم | J15: نعم
A16: 12
A17: 13
A20: عضو الفريق التنفيذي: عبدالله خالد العتيبي | الفريق التنفيذي بقطاع السر | وزارة التعليم
A21: عبدالله خالد العتيبي

Sheet تعليمات
A1: وزارة التعليم | المملكة العربية السعودية
A2: تعليمات استخدام الملف — لوحة التحكم للمدارس المسندة | العام الدراسي 1448هـ | G2: 🏠 العودة للصفحة الرئيسية
A3: عضو الفريق التنفيذي: عبدالله خالد العتيبي | الفريق التنفيذي بقطاع السر
A5: 📋 طريقة الاستخدام
A6: 1. انتقل إلى ورقة «بيانات المدارس» وأدخل بيانات كل مدرسة في الصفوف بدءاً من الصف 5.
A7: 2. الأعمدة الأساسية: اسم المدرسة (B) ، الرقم الوزاري (C) ، اسم المدير (D) ، جوال المدير (E) ، اسم الوكيل (F) ، جوال الوكيل (G).
A8: 3. عمود «عدد المعلمين» (H): أدخل الرقم الصحيح — هذا العمود يغذي لوحة التحكم والإحصائيات تلقائياً.
A9: 4. عمود «توفر التخصصات» (I): نعم / أو وصف العجز (مثل: عجز بدنية وفنية).
A10: 5. عمود «دخول المعلمين» (J) و«دخول الطلاب المنصة» (L): سجّل الحالة (تم / باقي 1 / يحتاج متابعة ...).
A11: 6. عمود «نتيجة تقرير المدرسة العامة 2026» (N): أدخل إحدى القيم: ممتاز | جيد جداً | جيد | مقبول | ضعيف — لتتلون الخلية تلقائياً.
A12: 7. الأعمدة R إلى V جاهزة للتعبئة (موجه صحي، موجه طلابي، دراسة النتائج، خطة المدرسة، أعمال المدير) وتظهر في ورقة التحليل.
A13: 8. يمكنك إضافة مدارس جديدة في الصفوف الفارغة حتى الصف 17، مع الحفاظ على تسلسل الأرقام في العمود A.
A14: 9. لا تحذف أو تغيّر أسماء الأوراق أو عناوين الأعمدة الأساسية حتى لا تتأثر الصيغ.
A16: 🔽 القوائم المنسدلة والتنسيق الشرطي
... A31: عضو الفريق التنفيذي: عبدالله خالد العتيبي | الفريق التنفيذي بقطاع السر | وزارة التعليم

Sheet متابعة دخول المنصة
A1: متابعة نسب دخول المعلمين والطلاب لمنصة مدرستي 1448 | GP1: 🏠 العودة للرئيسية
A2: 🏠 العودة للصفحة الرئيسية
A3: اسم عضو الفريق التنفيذي: عبدالله خالد العتيبي | H3: الأسبوع الأول من بداية الفصل الدراسي الأول | AB3: الأسبوع الثاني | AV3: الأسبوع 3 | BP3: الأسبوع 4 | CJ3: الأسبوع 5 | DD3: الأسبوع 6 | DX3: الأسبوع 7 | ER3: الأسبوع 8 | FL3: الأسبوع 9 | GF3: الأسبوع 10 | GZ3: الأسبوع 11 | HT3: الأسبوع 12 | IN3: الأسبوع 13 | JH3: الأسبوع 14 | KB3: الأسبوع 15 | KV3: الأسبوع 16 | LP3: الأسبوع 17 | MJ3: الأسبوع 18 | ND3: الأسبوع 19
H4: الأحد 10 / 3 | L4: الاثنين 11 / 3 | P4: الثلاثاء 12 / 3 | T4: الأربعاء 13 / 3 | X4: الخميس 14 / 3 | AB4: الأحد 17/3 | AF4: الاثنين18/3 | AJ4: الثلاثاء19/3 | AN4: الأربعاء20/3 | AR4: الخميس21/3 | AV4: الأحد24/3 | AZ4: الاثنين25/3 | BD4: الثلاثاء26/3 | BH4: الأربعاء 27/3 | BL4: الخميس28/3 | BP4: الأحد2/4 | BT4: الاثنين3/4 | BX4: الثلاثاء4/4 | CB4: الأربعاء5/4 | CF4: الخميس6/4 | CJ4: الأحد9/4 | CN4: الاثنين10/4 | CR4: الثلاثاء11/4 | CV4: الأربعاء12/4 | CZ4: الخميس13/7 | DD4: الأحد16/4 | DH4: الاثنين17/4 | DL4: الثلاثاء18/4 | DP4: الأربعاء19/4 | DT4: الخميس20/4 | DX4: الأحد23/4 | EB4: الاثنين24/4 | EF4: الثلاثاء | EJ4: الأربعاء | EN4: الخميس | ER4: الأحد | EV4: الاثنين | EZ4: الثلاثاء | FD4: الأربعاء | FH4: الخميس | FL4: الأحد | FP4: الاثنين | FT4: الثلاثاء | FX4: الأربعاء | GB4: الخميس | GF4: الأحد | GJ4: الاثنين | GN4: الثلاثاء | GR4: الأربعاء | GV4: الخميس | GZ4: الأحد | HD4: الاثنين | HH4: الثلاثاء | HL4: الأربعاء | HP4: الخميس | HT4: الأحد | HX4: الاثنين | IB4: الثلاثاء | IF4: الأربعاء | IJ4: الخميس | IN4: الأحد | IR4: الاثنين | IV4: الثلاثاء | IZ4: الأربعاء | JD4: الخميس | JH4: الأحد | JL4: الاثنين | JP4: الثلاثاء | JT4: الأربعاء | JX4: الخميس | KB4: الأحد | KF4: الاثنين | KJ4: الثلاثاء | KN4: الأربعاء | KR4: الخميس | KV4: الأحد | KZ4: الاثنين | LD4: الثلاثاء | LH4: الأربعاء | LL4: الخميس | LP4: الأحد | LT4: الاثنين | LX4: الثلاثاء | MB4: الأربعاء | MF4: الخميس | MJ4: الأحد | MN4: الاثنين | MR4: الثلاثاء | MV4: الأربعاء | MZ4: الخميس | ND4: الأحد | NH4: الاثنين | NL4: الثلاثاء | NP4: الأربعاء | NT4: الخميس
A5: م | B5: المدرسة | C5: المرحلة الدراسية | D5: الرقم الوزاري | E5: جنس المدرسة | F5: العدد الكلي للمعلمين | G5: العدد الكلي للطلاب | H5: دخول المعلمين | I5: نسبة المعلمين | J5: دخول الطلاب | K5: نسبة الطلاب | L5: دخول المعلمين | M5: نسبة المعلمين | N5: دخول الطلاب | O5: نسبة الطلاب | P5: دخول المعلمين | Q5: نسبة المعلمين | R5: دخول الطلاب | S5: نسبة الطلاب | T5: دخول المعلمين | U5: نسبة المعلمين | V5: دخول الطلاب | W5: نسبة الطلاب | X5: دخول المعلمين | Y5: نسبة المعلمين | Z5: دخول الطلاب | AA5: نسبة الطلاب | AB5: دخول المعلمين | AC5: نسبة المعلمين | AD5: دخول الطلاب | AE5: نسبة الطلاب | AF5: دخول المعلمين | AG5: نسبة المعلمين | AH5: دخول الطلاب | AI5: نسبة الطلاب | AJ5: دخول المعلمين | AK5: نسبة المعلمين | AL5: دخول الطلاب | AM5: نسبة الطلاب | AN5: دخول المعلمين | AO5: نسبة المعلمين | AP5: دخول الطلاب | AQ5: نسبة الطلاب | AR5: دخول المعلمين | AS5: نسبة المعلمين | AT5: دخول الطلاب | AU5: نسبة الطلاب | AV5: دخول المعلمين | AW5: نسبة المعلمين | AX5: دخول الطلاب | AY5: نسبة الطلاب | AZ5: دخول المعلمين | BA5: نسبة المعلمين | BB5: دخول الطلاب | BC5: نسبة الطلاب | BD5: دخول المعلمين | BE5: نسبة المعلمين | BF5: دخول الطلاب | BG5: نسبة الطلاب | BH5: دخول المعلمين | BI5: نسبة المعلمين | BJ5: دخول الطلاب | BK5: نسبة الطلاب | BL5: دخول المعلمين | BM5: نسبة المعلمين | BN5: دخول الطلاب | BO5: نسبة الطلاب | BP5: دخول المعلمين | BQ5: نسبة المعلمين | BR5: دخول الطلاب | BS5: نسبة الطلاب | BT5: دخول المعلمين | BU5: نسبة المعلمين | BV5: دخول الطلاب | BW5: نسبة الطلاب | BX5: دخول المعلمين | BY5: نسبة المعلمين | BZ5: دخول الطلاب | CA5: نسبة الطلاب | CB5: دخول المعلمين | CC5: نسبة المعلمين | CD5: دخول الطلاب | CE5: نسبة الطلاب | CF5: دخول المعلمين | CG5: نسبة المعلمين | CH5: دخول الطلاب | CI5: نسبة الطلاب | CJ5: دخول المعلمين | CK5: نسبة المعلمين | CL5: دخول الطلاب | CM5: نسبة الطلاب | CN5: دخول المعلمين | CO5: نسبة المعلمين | CP5: دخول الطلاب | CQ5: نسبة الطلاب | CR5: دخول المعلمين | CS5: نسبة المعلمين | CT5: دخول الطلاب | CU5: نسبة الطلاب | CV5: دخول المعلمين | CW5: نسبة المعلمين | CX5: دخول الطلاب | CY5: نسبة الطلاب | CZ5: دخول المعلمين | DA5: نسبة المعلمين | DB5: دخول الطلاب | DC5: نسبة الطلاب | DD5: دخول المعلمين | DE5: نسبة المعلمين | DF5: دخول الطلاب | DG5: نسبة الطلاب | DH5: دخول المعلمين | DI5: نسبة المعلمين | DJ5: دخول الطلاب | DK5: نسبة الطلاب | DL5: دخول المعلمين | DM5: نسبة المعلمين | DN5: دخول الطلاب | DO5: نسبة الطلاب | DP5: دخول المعلمين | DQ5: نسبة المعلمين | DR5: دخول الطلاب | DS5: نسبة الطلاب | DT5: دخول المعلمين | DU5: نسبة المعلمين | DV5: دخول الطلاب | DW5: نسبة الطلاب | DX5: دخول المعلمين | DY5: نسبة المعلمين | DZ5: دخول الطلاب | EA5: نسبة الطلاب | EB5: دخول المعلمين | EC5: نسبة المعلمين | ED5: دخول الطلاب | EE5: نسبة الطلاب | EF5: دخول المعلمين | EG5: نسبة المعلمين | EH5: دخول الطلاب | EI5: نسبة الطلاب | EJ5: دخول المعلمين | EK5: نسبة المعلمين | EL5: دخول الطلاب | EM5: نسبة الطلاب | EN5: دخول المعلمين | EO5: نسبة المعلمين | EP5: دخول الطلاب | EQ5: نسبة الطلاب | ER5: دخول المعلمين | ES5: نسبة المعلمين | ET5: دخول الطلاب | EU5: نسبة الطلاب | EV5: دخول المعلمين | EW5: نسبة المعلمين | EX5: دخول الطلاب | EY5: نسبة الطلاب | EZ5: دخول المعلمين | FA5: نسبة المعلمين | FB5: دخول الطلاب | FC5: نسبة الطلاب | FD5: دخول المعلمين | FE5: نسبة المعلمين | FF5: دخول الطلاب | FG5: نسبة الطلاب | FH5: دخول المعلمين | FI5: نسبة المعلمين | FJ5: دخول الطلاب | FK5: نسبة الطلاب | FL5: دخول المعلمين | FM5: نسبة المعلمين | FN5: دخول الطلاب | FO5: نسبة الطلاب | FP5: دخول المعلمين | FQ5: نسبة المعلمين | FR5: دخول الطلاب | FS5: نسبة الطلاب | FT5: دخول المعلمين | FU5: نسبة المعلمين | FV5: دخول الطلاب | FW5: نسبة الطلاب | FX5: دخول المعلمين | FY5: نسبة المعلمين | FZ5: دخول الطلاب | GA5: نسبة الطلاب | GB5: دخول المعلمين | GC5: نسبة المعلمين | GD5: دخول الطلاب | GE5: نسبة الطلاب | GF5: دخول المعلمين | GG5: نسبة المعلمين | GH5: دخول الطلاب | GI5: نسبة الطلاب | GJ5: دخول المعلمين | GK5: نسبة المعلمين | GL5: دخول الطلاب | GM5: نسبة الطلاب | GN5: دخول المعلمين | GO5: نسبة المعلمين | GP5: دخول الطلاب | GQ5: نسبة الطلاب | GR5: دخول المعلمين | GS5: نسبة المعلمين | GT5: دخول الطلاب | GU5: نسبة الطلاب | GV5: دخول المعلمين | GW5: نسبة المعلمين | GX5: دخول الطلاب | GY5: نسبة الطلاب | GZ5: دخول المعلمين | HA5: نسبة المعلمين | HB5: دخول الطلاب | HC5: نسبة الطلاب | HD5: دخول المعلمين | HE5: نسبة المعلمين | HF5: دخول الطلاب | HG5: نسبة الطلاب | HH5: دخول المعلمين | HI5: نسبة المعلمين | HJ5: دخول الطلاب | HK5: نسبة الطلاب | HL5: دخول المعلمين | HM5: نسبة المعلمين | HN5: دخول الطلاب | HO5: نسبة الطلاب | HP5: دخول المعلمين | HQ5: نسبة المعلمين | HR5: دخول الطلاب | HS5: نسبة الطلاب | HT5: دخول المعلمين | HU5: نسبة المعلمين | HV5: دخول الطلاب | HW5: نسبة الطلاب | HX5: دخول المعلمين | HY5: نسبة المعلمين | HZ5: دخول الطلاب | IA5: نسبة الطلاب | IB5: دخول المعلمين | IC5: نسبة المعلمين | ID5: دخول الطلاب | IE5: نسبة الطلاب | IF5: دخول المعلمين | IG5: نسبة المعلمين | IH5: دخول الطلاب | II5: نسبة الطلاب | IJ5: دخول المعلمين | IK5: نسبة المعلمين | IL5: دخول الطلاب | IM5: نسبة الطلاب | IN5: دخول المعلمين | IO5: نسبة المعلمين | IP5: دخول الطلاب | IQ5: نسبة الطلاب | IR5: دخول المعلمين | IS5: نسبة المعلمين | IT5: دخول الطلاب | IU5: نسبة الطلاب | IV5: دخول المعلمين | IW5: نسبة المعلمين | IX5: دخول الطلاب | IY5: نسبة الطلاب | IZ5: دخول المعلمين | JA5: نسبة المعلمين | JB5: دخول الطلاب | JC5: نسبة الطلاب | JD5: دخول المعلمين | JE5: نسبة المعلمين | JF5: دخول الطلاب | JG5: نسبة الطلاب | JH5: دخول المعلمين | JI5: نسبة المعلمين | JJ5: دخول الطلاب | JK5: نسبة الطلاب | JL5: دخول المعلمين | JM5: نسبة المعلمين | JN5: دخول الطلاب | JO5: نسبة الطلاب | JP5: دخول المعلمين | JQ5: نسبة المعلمين | JR5: دخول الطلاب | JS5: نسبة الطلاب | JT5: دخول المعلمين | JU5: نسبة المعلمين | JV5: دخول الطلاب | JW5: نسبة الطلاب | JX5: دخول المعلمين | JY5: نسبة المعلمين | JZ5: دخول الطلاب | KA5: نسبة الطلاب | KB5: دخول المعلمين | KC5: نسبة المعلمين | KD5: دخول الطلاب | KE5: نسبة الطلاب | KF5: دخول المعلمين | KG5: نسبة المعلمين | KH5: دخول الطلاب | KI5: نسبة الطلاب | KJ5: دخول المعلمين | KK5: نسبة المعلمين | KL5: دخول الطلاب | KM5: نسبة الطلاب | KN5: دخول المعلمين | KO5: نسبة المعلمين | KP5: دخول الطلاب | KQ5: نسبة الطلاب | KR5: دخول المعلمين | KS5: نسبة المعلمين | KT5: دخول الطلاب | KU5: نسبة الطلاب | KV5: دخول المعلمين | KW5: نسبة المعلمين | KX5: دخول الطلاب | KY5: نسبة الطلاب | KZ5: دخول المعلمين | LA5: نسبة المعلمين | LB5: دخول الطلاب | LC5: نسبة الطلاب | LD5: دخول المعلمين | LE5: نسبة المعلمين | LF5: دخول الطلاب | LG5: نسبة الطلاب | LH5: دخول المعلمين | LI5: نسبة المعلمين | LJ5: دخول الطلاب | LK5: نسبة الطلاب | LL5: دخول المعلمين | LM5: نسبة المعلمين | LN5: دخول الطلاب | LO5: نسبة الطلاب | LP5: دخول المعلمين | LQ5: نسبة المعلمين | LR5: دخول الطلاب | LS5: نسبة الطلاب | LT5: دخول المعلمين | LU5: نسبة المعلمين | LV5: دخول الطلاب | LW5: نسبة الطلاب | LX5: دخول المعلمين | LY5: نسبة المعلمين | LZ5: دخول الطلاب | MA5: نسبة الطلاب | MB5: دخول المعلمين | MC5: نسبة المعلمين | MD5: دخول الطلاب | ME5: نسبة الطلاب | MF5: دخول المعلمين | MG5: نسبة المعلمين | MH5: دخول الطلاب | MI5: نسبة الطلاب | MJ5: دخول المعلمين | MK5: نسبة المعلمين | ML5: دخول الطلاب | MM5: نسبة الطلاب | MN5: دخول المعلمين | MO5: نسبة المعلمين | MP5: دخول الطلاب | MQ5: نسبة الطلاب | MR5: دخول المعلمين | MS5: نسبة المعلمين | MT5: دخول الطلاب | MU5: نسبة الطلاب | MV5: دخول المعلمين | MW5: نسبة المعلمين | MX5: دخول الطلاب | MY5: نسبة الطلاب | MZ5: دخول المعلمين | NA5: نسبة المعلمين | NB5: دخول الطلاب | NC5: نسبة الطلاب | ND5: دخول المعلمين | NE5: نسبة المعلمين | NF5: دخول الطلاب | NG5: نسبة الطلاب | NH5: دخول المعلمين | NI5: نسبة المعلمين | NJ5: دخول الطلاب | NK5: نسبة الطلاب | NL5: دخول المعلمين | NM5: نسبة المعلمين | NN5: دخول الطلاب | NO5: نسبة الطلاب | NP5: دخول المعلمين | NQ5: نسبة المعلمين | NR5: دخول الطلاب | NS5: نسبة الطلاب | NT5: دخول المعلمين | NU5: نسبة المعلمين | NV5: دخول الطلاب | NW5: نسبة الطلاب
A6: 1 | B6: الارطاوي بالسر | C6: الثانوية | D6: m3917285 | E6: بنين | F6: 8 | G6: 50 | H6: 8 | I6: =IF(OR($F6="",H6=""),"",IF($F6=0,0,H6/$F6)) -> 1 | J6: 10 | K6: =IF(OR($G6="",J6=""),"",IF($G6=0,0,J6/$G6)) -> 0.2 | L6: 8 | M6: =IF(OR($F6="",L6=""),"",IF($F6=0,0,L6/$F6)) -> 1 | N6: 10 | O6: =IF(OR($G6="",N6=""),"",IF($G6=0,0,N6/$G6)) -> 0.2 | P6: 8 | Q6: =IF(OR($F6="",P6=""),"",IF($F6=0,0,P6/$F6)) -> 1 | R6: 13 | S6: =IF(OR($G6="",R6=""),"",IF($G6=0,0,R6/$G6)) -> 0.26 | T6: 8 | U6: =IF(OR($F6="",T6=""),"",IF($F6=0,0,T6/$F6)) -> 1 | V6: 18 | W6: =IF(OR($G6="",V6=""),"",IF($G6=0,0,V6/$G6)) -> 0.36 | X6: 8 | Y6: =IF(OR($F6="",X6=""),"",IF($F6=0,0,X6/$F6)) -> 1 | Z6: 21 | AA6: =IF(OR($G6="",Z6=""),"",IF($G6=0,0,Z6/$G6)) -> 0.42 | AB6: 8 | AC6: =IF(OR($F6="",AB6=""),"",IF($F6=0,0,AB6/$F6)) -> 1 | AD6: 21 | AE6: =IF(OR($G6="",AD6=""),"",IF($G6=0,0,AD6/$G6)) -> 0.42 | AF6: 8 | AG6: =IF(OR($F6="",AF6=""),"",IF($F6=0,0,AF6/$F6)) -> 1 | AH6: 24 | AI6: =IF(OR($G6="",AH6=""),"",IF($G6=0,0,AH6/$G6)) -> 0.48 | AJ6: 8 | AK6: =IF(OR($F6="",AJ6=""),"",IF($F6=0,0,AJ6/$F6)) -> 1 | AL6: 27 | AM6: =IF(OR($G6="",AL6=""),"",IF($G6=0,0,AL6/$G6)) -> 0.54 | AN6: 8 | AO6: =IF(OR($F6="",AN6=""),"",IF($F6=0,0,AN6/$F6)) -> 1 | AP6: 29 | AQ6: =IF(OR($G6="",AP6=""),"",IF($G6=0,0,AP6/$G6)) -> 0.58 | AR6: 8 | AS6: =IF(OR($F6="",AR6=""),"",IF($F6=0,0,AR6/$F6)) -> 1 | AT6: 29 | AU6: =IF(OR($G6="",AT6=""),"",IF($G6=0,0,AT6/$G6)) -> 0.58 | AV6: 8 | AW6: =IF(OR($F6="",AV6=""),"",IF($F6=0,0,AV6/$F6)) -> 1 | AX6: 41 | AY6: =IF(OR($G6="",AX6=""),"",IF($G6=0,0,AX6/$G6)) -> 0.82 | AZ6: 8 | BA6: =IF(OR($F6="",AZ6=""),"",IF($F6=0,0,AZ6/$F6)) -> 1 | BB6: 42 | BC6: =IF(OR($G6="",BB6=""),"",IF($G6=0,0,BB6/$G6)) -> 0.84 | BD6: 8 | BE6: =IF(OR($F6="",BD6=""),"",IF($F6=0,0,BD6/$F6)) -> 1 | BF6: 45 | BG6: =IF(OR($G6="",BF6=""),"",IF($G6=0,0,BF6/$G6)) -> 0.9 | BH6: 8 | BI6: =IF(OR($F6="",BH6=""),"",IF($F6=0,0,BH6/$F6)) -> 1 | BJ6: 47 | BK6: =IF(OR($G6="",BJ6=""),"",IF($G6=0,0,BJ6/$G6)) -> 0.94 | BL6: 8 | BM6: =IF(OR($F6="",BL6=""),"",IF($F6=0,0,BL6/$F6)) -> 1 | BN6: 47 | BO6: =IF(OR($G6="",BN6=""),"",IF($G6=0,0,BN6/$G6)) -> 0.94 | BP6: 8 | BQ6: =IF(OR($F6="",BP6=""),"",IF($F6=0,0,BP6/$F6)) -> 1 | BR6: 47 | BS6: =IF(OR($G6="",BR6=""),"",IF($G6=0,0,BR6/$G6)) -> 0.94 | BT6: 8 | BU6: =IF(OR($F6="",BT6=""),"",IF($F6=0,0,BT6/$F6)) -> 1 | BV6: 48 | BW6: =IF(OR($G6="",BV6=""),"",IF($G6=0,0,BV6/$G6)) -> 0.96 | BX6: 8 | BY6: =IF(OR($F6="",BX6=""),"",IF($F6=0,0,BX6/$F6)) -> 1 | BZ6: 48 | CA6: =IF(OR($G6="",BZ6=""),"",IF($G6=0,0,BZ6/$G6)) -> 0.96 | CB6: 8 | CC6: =IF(OR($F6="",CB6=""),"",IF($F6=0,0,CB6/$F6)) -> 1 | CD6: 47 | CE6: 94.0% | CF6: 8 | CG6: 100.0% | CH6: 49 | CI6: =IF(OR($G6="",CH6=""),"",IF($G6=0,0,CH6/$G6)) -> 0.98 | CJ6: 8 | CK6: =IF(OR($F6="",CJ6=""),"",IF($F6=0,0,CJ6/$F6)) -> 1 | CL6: 49 | CM6: =IF(OR($G6="",CL6=""),"",IF($G6=0,0,CL6/$G6)) -> 0.98 | CN6: 8 | CO6: =IF(OR($F6="",CN6=""),"",IF($F6=0,0,CN6/$F6)) -> 1 | CP6: 49 | CQ6: =IF(OR($G6="",CP6=""),"",IF($G6=0,0,CP6/$G6)) -> 0.98 | CR6: 8 | CS6: =IF(OR($F6="",CR6=""),"",IF($F6=0,0,CR6/$F6)) -> 1 | CT6: 49 | CU6: =IF(OR($G6="",CT6=""),"",IF($G6=0,0,CT6/$G6)) -> 0.98 | CW6: =IF(OR($F6="",CV6=""),"",IF($F6=0,0,CV6/$F6)) | CY6: =IF(OR($G6="",CX6=""),"",IF($G6=0,0,CX6/$G6)) | DA6: =IF(OR($F6="",CZ6=""),"",IF($F6=0,0,CZ6/$F6)) | DC6: =IF(OR($G6="",DB6=""),"",IF($G6=0,0,DB6/$G6)) | DD6: 8 | DE6: =IF(OR($F6="",DD6=""),"",IF($F6=0,0,DD6/$F6)) -> 1 | DF6: 49 | DG6: =IF(OR($G6="",DF6=""),"",IF($G6=0,0,DF6/$G6)) -> 0.98 | DH6: 8 | DI6: =IF(OR($F6="",DH6=""),"",IF($F6=0,0,DH6/$F6)) -> 1 | DJ6: 50 | DK6: =IF(OR($G6="",DJ6=""),"",IF($G6=0,0,DJ6/$G6)) -> 1 | DL6: 8 | DM6: =IF(OR($F6="",DL6=""),"",IF($F6=0,0,DL6/$F6)) -> 1 | DN6: 50 | DO6: =IF(OR($G6="",DN6=""),"",IF($G6=0,0,DN6/$G6)) -> 1 | DP6: 8 | DQ6: =IF(OR($F6="",DP6=""),"",IF($F6=0,0,DP6/$F6)) -> 1 | DR6: 50 | DS6: =IF(OR($G6="",DR6=""),"",IF($G6=0,0,DR6/$G6)) -> 1 | DT6: 8 | DU6: =IF(OR($F6="",DT6=""),"",IF($F6=0,0,DT6/$F6)) -> 1 | DV6: 50 | DW6: =IF(OR($G6="",DV6=""),"",IF($G6=0,0,DV6/$G6)) -> 1 | DX6: 8 | DY6: =IF(OR($F6="",DX6=""),"",IF($F6=0,0,DX6/$F6)) -> 1 | DZ6: 50 | EA6: =IF(OR($G6="",DZ6=""),"",IF($G6=0,0,DZ6/$G6)) -> 1 | EB6: 8 | EC6: =IF(OR($F6="",EB6=""),"",IF($F6=0,0,EB6/$F6)) -> 1 | ED6: 50 | EE6: =IF(OR($G6="",ED6=""),"",IF($G6=0,0,ED6/$G6)) -> 1 | EF6: 8 | EG6: =IF(OR($F6="",EF6=""),"",IF($F6=0,0,EF6/$F6)) -> 1 | EH6: 50 | EI6: =IF(OR($G6="",EH6=""),"",IF($G6=0,0,EH6/$G6)) -> 1 | EJ6: 8 | EK6: =IF(OR($F6="",EJ6=""),"",IF($F6=0,0,EJ6/$F6)) -> 1 | EL6: 50 | EM6: =IF(OR($G6="",EL6=""),"",IF($G6=0,0,EL6/$G6)) -> 1 | EN6: 8 | EO6: =IF(OR($F6="",EN6=""),"",IF($F6=0,0,EN6/$F6)) -> 1 | EP6: 50 | EQ6: =IF(OR($G6="",EP6=""),"",IF($G6=0,0,EP6/$G6)) -> 1 | ER6: 8 | ES6: =IF(OR($F6="",ER6=""),"",IF($F6=0,0,ER6/$F6)) -> 1 | ET6: 50 | EU6: =IF(OR($G6="",ET6=""),"",IF($G6=0,0,ET6/$G6)) -> 1 | EV6: 8 | EW6: =IF(OR($F6="",EV6=""),"",IF($F6=0,0,EV6/$F6)) -> 1 | EX6: 50 | EY6: =IF(OR($G6="",EX6=""),"",IF($G6=0,0,EX6/$G6)) -> 1 | EZ6: 8 | FA6: =IF(OR($F6="",EZ6=""),"",IF($F6=0,0,EZ6/$F6)) -> 1 | FB6: 50 | FC6: =IF(OR($G6="",FB6=""),"",IF($G6=0,0,FB6/$G6)) -> 1 | FD6: 8 | FE6: =IF(OR($F6="",FD6=""),"",IF($F6=0,0,FD6/$F6)) -> 1 | FF6: 50 | FG6: =IF(OR($G6="",FF6=""),"",IF($G6=0,0,FF6/$G6)) -> 1 | FH6: 8 | FI6: =IF(OR($F6="",FH6=""),"",IF($F6=0,0,FH6/$F6)) -> 1 | FJ6: 50 | FK6: 100 | FL6: 8 | FM6: =IF(OR($F6="",FL6=""),"",IF($F6=0,0,FL6/$F6)) -> 1 | FO6: =IF(OR($G6="",FN6=""),"",IF($G6=0,0,FN6/$G6)) | FQ6: =IF(OR($F6="",FP6=""),"",IF($F6=0,0,FP6/$F6)) | FS6: =IF(OR($G6="",FR6=""),"",IF($G6=0,0,FR6/$G6)) | FU6: =IF(OR($F6="",FT6=""),"",IF($F6=0,0,FT6/$F6)) | FW6: =IF(OR($G6="",FV6=""),"",IF($G6=0,0,FV6/$G6)) | FY6: =IF(OR($F6="",FX6=""),"",IF($F6=0,0,FX6/$F6)) | GA6: =IF(OR($G6="",FZ6=""),"",IF($G6=0,0,FZ6/$G6)) | GC6: =IF(OR($F6="",GB6=""),"",IF($F6=0,0,GB6/$F6)) | GE6: =IF(OR($G6="",GD6=""),"",IF($G6=0,0,GD6/$G6)) | GG6: =IF(OR($F6="",GF6=""),"",IF($F6=0,0,GF6/$F6)) | GI6: =IF(OR($G6="",GH6=""),"",IF($G6=0,0,GH6/$G6)) | GK6: =IF(OR($F6="",GJ6=""),"",IF($F6=0,0,GJ6/$F6)) | GM6: =IF(OR($G6="",GL6=""),"",IF($G6=0,0,GL6/$G6)) | GO6: =IF(OR($F6="",GN6=""),"",IF($F6=0,0,GN6/$F6)) | GQ6: =IF(OR($G6="",GP6=""),"",IF($G6=0,0,GP6/$G6)) | GS6: =IF(OR($F6="",GR6=""),"",IF($F6=0,0,GR6/$F6)) | GU6: =IF(OR($G6="",GT6=""),"",IF($G6=0,0,GT6/$G6)) | GW6: =IF(OR($F6="",GV6=""),"",IF($F6=0,0,GV6/$F6)) | GY6: =IF(OR($G6="",GX6=""),"",IF($G6=0,0,GX6/$G6)) | HA6: =IF(OR($F6="",GZ6=""),"",IF($F6=0,0,GZ6/$F6)) | HC6: =IF(OR($G6="",HB6=""),"",IF($G6=0,0,HB6/$G6)) | HE6: =IF(OR($F6="",HD6=""),"",IF($F6=0,0,HD6/$F6)) | HG6: =IF(OR($G6="",HF6=""),"",IF($G6=0,0,HF6/$G6)) | HI6: =IF(OR($F6="",HH6=""),"",IF($F6=0,0,HH6/$F6)) | HK6: =IF(OR($G6="",HJ6=""),"",IF($G6=0,0,HJ6/$G6)) | HM6: =IF(OR($F6="",HL6=""),"",IF($F6=0,0,HL6/$F6)) | HO6: =IF(OR($G6="",HN6=""),"",IF($G6=0,0,HN6/$G6)) | HQ6: =IF(OR($F6="",HP6=""),"",IF($F6=0,0,HP6/$F6)) | HS6: =IF(OR($G6="",HR6=""),"",IF($G6=0,0,HR6/$G6)) | HU6: =IF(OR($F6="",HT6=""),"",IF($F6=0,0,HT6/$F6)) | HW6: =IF(OR($G6="",HV6=""),"",IF($G6=0,0,HV6/$G6)) | HY6: =IF(OR($F6="",HX6=""),"",IF($F6=0,0,HX6/$F6)) | IA6: =IF(OR($G6="",HZ6=""),"",IF($G6=0,0,HZ6/$G6)) | IC6: =IF(OR($F6="",IB6=""),"",IF($F6=0,0,IB6/$F6)) | IE6: =IF(OR($G6="",ID6=""),"",IF($G6=0,0,ID6/$G6)) | IG6: =IF(OR($F6="",IF6=""),"",IF($F6=0,0,IF6/$F6)) | II6: =IF(OR($G6="",IH6=""),"",IF($G6=0,0,IH6/$G6)) | IK6: =IF(OR($F6="",IJ6=""),"",IF($F6=0,0,IJ6/$F6)) | IM6: =IF(OR($G6="",IL6=""),"",IF($G6=0,0,IL6/$G6)) | IO6: =IF(OR($F6="",IN6=""),"",IF($F6=0,0,IN6/$F6)) | IQ6: =IF(OR($G6="",IP6=""),"",IF($G6=0,0,IP6/$G6)) | IS6: =IF(OR($F6="",IR6=""),"",IF($F6=0,0,IR6/$F6)) | IU6: =IF(OR($G6="",IT6=""),"",IF($G6=0,0,IT6/$G6)) | IW6: =IF(OR($F6="",IV6=""),"",IF($F6=0,0,IV6/$F6)) | IY6: =IF(OR($G6="",IX6=""),"",IF($G6=0,0,IX6/$G6)) | JA6: =IF(OR($F6="",IZ6=""),"",IF($F6=0,0,IZ6/$F6)) | JC6: =IF(OR($G6="",JB6=""),"",IF($G6=0,0,JB6/$G6)) | JE6: =IF(OR($F6="",JD6=""),"",IF($F6=0,0,JD6/$F6)) | JG6: =IF(OR($G6="",JF6=""),"",IF($G6=0,0,JF6/$G6)) | JI6: =IF(OR($F6="",JH6=""),"",IF($F6=0,0,JH6/$F6)) | JK6: =IF(OR($G6="",JJ6=""),"",IF($G6=0,0,JJ6/$G6)) | JM6: =IF(OR($F6="",JL6=""),"",IF($F6=0,0,JL6/$F6)) | JO6: =IF(OR($G6="",JN6=""),"",IF($G6=0,0,JN6/$G6)) | JQ6: =IF(OR($F6="",JP6=""),"",IF($F6=0,0,JP6/$F6)) | JS6: =IF(OR($G6="",JR6=""),"",IF($G6=0,0,JR6/$G6)) | JU6: =IF(OR($F6="",JT6=""),"",IF($F6=0,0,JT6/$F6)) | JW6: =IF(OR($G6="",JV6=""),"",IF($G6=0,0,JV6/$G6)) | JY6: =IF(OR($F6="",JX6=""),"",IF($F6=0,0,JX6/$F6)) | KA6: =IF(OR($G6="",JZ6=""),"",IF($G6=0,0,JZ6/$G6)) | KC6: =IF(OR($F6="",KB6=""),"",IF($F6=0,0,KB6/$F6)) | KE6: =IF(OR($G6="",KD6=""),"",IF($G6=0,0,KD6/$G6)) | KG6: =IF(OR($F6="",KF6=""),"",IF($F6=0,0,KF6/$F6)) | KI6: =IF(OR($G6="",KH6=""),"",IF($G6=0,0,KH6/$G6)) | KK6: =IF(OR($F6="",KJ6=""),"",IF($F6=0,0,KJ6/$F6)) | KM6: =IF(OR($G6="",KL6=""),"",IF($G6=0,0,KL6/$G6)) | KO6: =IF(OR($F6="",KN6=""),"",IF($F6=0,0,KN6/$F6)) | KQ6: =IF(OR($G6="",KP6=""),"",IF($G6=0,0,KP6/$G6)) | KS6: =IF(OR($F6="",KR6=""),"",IF($F6=0,0,KR6/$F6)) | KU6: =IF(OR($G6="",KT6=""),"",IF($G6=0,0,KT6/$G6)) | KW6: =IF(OR($F6="",KV6=""),"",IF($F6=0,0,KV6/$F6)) | KY6: =IF(OR($G6="",KX6=""),"",IF($G6=0,0,KX6/$G6)) | LA6: =IF(OR($F6="",KZ6=""),"",IF($F6=0,0,KZ6/$F6)) | LC6: =IF(OR($G6="",LB6=""),"",IF($G6=0,0,LB6/$G6)) | LE6: =IF(OR($F6="",LD6=""),"",IF($F6=0,0,LD6/$F6)) | LG6: =IF(OR($G6="",LF6=""),"",IF($G6=0,0,LF6/$G6)) | LI6: =IF(OR($F6="",LH6=""),"",IF($F6=0,0,LH6/$F6)) | LK6: =IF(OR($G6="",LJ6=""),"",IF($G6=0,0,LJ6/$G6)) | LM6: =IF(OR($F6="",LL6=""),"",IF($F6=0,0,LL6/$F6)) | LO6: =IF(OR($G6="",LN6=""),"",IF($G6=0,0,LN6/$G6)) | LQ6: =IF(OR($F6="",LP6=""),"",IF($F6=0,0,LP6/$F6)) | LS6: =IF(OR($G6="",LR6=""),"",IF($G6=0,0,LR6/$G6)) | LU6: =IF(OR($F6="",LT6=""),"",IF($F6=0,0,LT6/$F6)) | LW6: =IF(OR($G6="",LV6=""),"",IF($G6=0,0,LV6/$G6)) | LY6: =IF(OR($F6="",LX6=""),"",IF($F6=0,0,LX6/$F6)) | MA6: =IF(OR($G6="",LZ6=""),"",IF($G6=0,0,LZ6/$G6)) | MC6: =IF(OR($F6="",MB6=""),"",IF($F6=0,0,MB6/$F6)) | ME6: =IF(OR($G6="",MD6=""),"",IF($G6=0,0,MD6/$G6)) | MG6: =IF(OR($F6="",MF6=""),"",IF($F6=0,0,MF6/$F6)) | MI6: =IF(OR($G6="",MH6=""),"",IF($G6=0,0,MH6/$G6)) | MK6: =IF(OR($F6="",MJ6=""),"",IF($F6=0,0,MJ6/$F6)) | MM6: =IF(OR($G6="",ML6=""),"",IF($G6=0,0,ML6/$G6)) | MO6: =IF(OR($F6="",MN6=""),"",IF($F6=0,0,MN6/$F6)) | MQ6: =IF(OR($G6="",MP6=""),"",IF($G6=0,0,MP6/$G6)) | MS6: =IF(OR($F6="",MR6=""),"",IF($F6=0,0,MR6/$F6)) | MU6: =IF(OR($G6="",MT6=""),"",IF($G6=0,0,MT6/$G6)) | MW6: =IF(OR($F6="",MV6=""),"",IF($F6=0,0,MV6/$F6)) | MY6: =IF(OR($G6="",MX6=""),"",IF($G6=0,0,MX6/$G6)) | NA6: =IF(OR($F6="",MZ6=""),"",IF($F6=0,0,MZ6/$F6)) | NC6: =IF(OR($G6="",NB6=""),"",IF($G6=0,0,NB6/$G6)) | NE6: =IF(OR($F6="",ND6=""),"",IF($F6=0,0,ND6/$F6)) | NG6: =IF(OR($G6="",NF6=""),"",IF($G6=0,0,NF6/$G6)) | NI6: =IF(OR($F6="",NH6=""),"",IF($F6=0,0,NH6/$F6)) | NK6: =IF(OR($G6="",NJ6=""),"",IF($G6=0,0,NJ6/$G6)) | NM6: =IF(OR($F6="",NL6=""),"",IF($F6=0,0,NL6/$F6)) | NO6: =IF(OR($G6="",NN6=""),"",IF($G6=0,0,NN6/$G6)) | NQ6: =IF(OR($F6="",NP6=""),"",IF($F6=0,0,NP6/$F6)) | NS6: =IF(OR($G6="",NR6=""),"",IF($G6=0,0,NR6/$G6)) | NU6: =IF(OR($F6="",NT6=""),"",IF($F6=0,0,NT6/$F6)) | NW6: =IF(OR($G6="",NV6=""),"",IF($G6=0,0,NV6/$G6))
A7: 2 | B7: الارطاوي بالسر | C7: المتوسطة | D7: 17229 | E7: بنين | F7: 10 | G7: 55 | H7: 10 | I7: =IF(OR($F7="",H7=""),"",IF($F7=0,0,H7/$F7)) -> 1 | J7: 15 | K7: =IF(OR($G7="",J7=""),"",IF($G7=0,0,J7/$G7)) -> 0.27272727 | L7: 10 | M7: =IF(OR($F7="",L7=""),"",IF($F7=0,0,L7/$F7)) -> 1 | N7: 17 | O7: =IF(OR($G7="",N7=""),"",IF($G7=0,0,N7/$G7)) -> 0.30909091 | P7: 10 | Q7: =IF(OR($F7="",P7=""),"",IF($F7=0,0,P7/$F7)) -> 1 | R7: 18 | S7: =IF(OR($G7="",R7=""),"",IF($G7=0,0,R7/$G7)) -> 0.32727273 | T7: 10 | U7: =IF(OR($F7="",T7=""),"",IF($F7=0,0,T7/$F7)) -> 1 | V7: 21 | W7: =IF(OR($G7="",V7=""),"",IF($G7=0,0,V7/$G7)) -> 0.38181818 | X7: 10 | Y7: =IF(OR($F7="",X7=""),"",IF($F7=0,0,X7/$F7)) -> 1 | Z7: 26 | AA7: =IF(OR($G7="",Z7=""),"",IF($G7=0,0,Z7/$G7)) -> 0.47272727 | AB7: 10 | AC7: =IF(OR($F7="",AB7=""),"",IF($F7=0,0,AB7/$F7)) -> 1 | AD7: 27 | AE7: =IF(OR($G7="",AD7=""),"",IF($G7=0,0,AD7/$G7)) -> 0.49090909 | AF7: 10 | AG7: =IF(OR($F7="",AF7=""),"",IF($F7=0,0,AF7/$F7)) -> 1 | AH7: 33 | AI7: =IF(OR($G7="",AH7=""),"",IF($G7=0,0,AH7/$G7)) -> 0.6 | AJ7: 10 | AK7: =IF(OR($F7="",AJ7=""),"",IF($F7=0,0,AJ7/$F7)) -> 1 | AL7: 36 | AM7: =IF(OR($G7="",AL7=""),"",IF($G7=0,0,AL7/$G7)) -> 0.65454545 | AN7: 10 | AO7: =IF(OR($F7="",AN7=""),"",IF($F7=0,0,AN7/$F7)) -> 1 | AP7: 36 | AQ7: =IF(OR($G7="",AP7=""),"",IF($G7=0,0,AP7/$G7)) -> 0.65454545 | AR7: 10 | AS7: =IF(OR($F7="",AR7=""),"",IF($F7=0,0,AR7/$F7)) -> 1 | AT7: 36 | AU7: =IF(OR($G7="",AT7=""),"",IF($G7=0,0,AT7/$G7)) -> 0.65454545 | AV7: 10 | AW7: =IF(OR($F7="",AV7=""),"",IF($F7=0,0,AV7/$F7)) -> 1 | AX7: 39 | AY7: =IF(OR($G7="",AX7=""),"",IF($G7=0,0,AX7/$G7)) -> 0.70909091 | AZ7: 10 | BA7: =IF(OR($F7="",AZ7=""),"",IF($F7=0,0,AZ7/$F7)) -> 1 | BB7: 39 | BC7: =IF(OR($G7="",BB7=""),"",IF($G7=0,0,BB7/$G7)) -> 0.70909091 | BD7: 10 | BE7: =IF(OR($F7="",BD7=""),"",IF($F7=0,0,BD7/$F7)) -> 1 | BF7: 41 | BG7: =IF(OR($G7="",BF7=""),"",IF($G7=0,0,BF7/$G7)) -> 0.74545455 | BH7: 10 | BI7: =IF(OR($F7="",BH7=""),"",IF($F7=0,0,BH7/$F7)) -> 1 | BJ7: 42 | BK7: =IF(OR($G7="",BJ7=""),"",IF($G7=0,0,BJ7/$G7)) -> 0.76363636 | BL7: 10 | BM7: =IF(OR($F7="",BL7=""),"",IF($F7=0,0,BL7/$F7)) -> 1 | BN7: 42 | BO7: =IF(OR($G7="",BN7=""),"",IF($G7=0,0,BN7/$G7)) -> 0.76363636 | BP7: 10 | BQ7: =IF(OR($F7="",BP7=""),"",IF($F7=0,0,BP7/$F7)) -> 1 | BR7: 45 | BS7: =IF(OR($G7="",BR7=""),"",IF($G7=0,0,BR7/$G7)) -> 0.81818182 | BT7: 10 | BU7: =IF(OR($F7="",BT7=""),"",IF($F7=0,0,BT7/$F7)) -> 1 | BV7: 45 | BW7: 0.81 | BX7: 10 | BY7: =IF(OR($F7="",BX7=""),"",IF($F7=0,0,BX7/$F7)) -> 1 | BZ7: 51 | CA7: =IF(OR($G7="",BZ7=""),"",IF($G7=0,0,BZ7/$G7)) -> 0.92727273 | CB7: 10 | CC7: =IF(OR($F7="",CB7=""),"",IF($F7=0,0,CB7/$F7)) -> 1 | CD7: 50 | CE7: =IF(OR($G7="",CD7=""),"",IF($G7=0,0,CD7/$G7)) -> 0.90909091 | CF7: 10 | CG7: =IF(OR($F7="",CF7=""),"",IF($F7=0,0,CF7/$F7)) -> 1 | CH7: 52 | CI7: =IF(OR($G7="",CH7=""),"",IF($G7=0,0,CH7/$G7)) -> 0.94545455 | CJ7: 10 | CK7: =IF(OR($F7="",CJ7=""),"",IF($F7=0,0,CJ7/$F7)) -> 1 | CL7: 53 | CM7: =IF(OR($G7="",CL7=""),"",IF($G7=0,0,CL7/$G7)) -> 0.96363636 | CN7: 10 | CO7: =IF(OR($F7="",CN7=""),"",IF($F7=0,0,CN7/$F7)) -> 1 | CP7: 54 | CQ7: =IF(OR($G7="",CP7=""),"",IF($G7=0,0,CP7/$G7)) -> 0.98181818 | CR7: 10 | CS7: =IF(OR($F7="",CR7=""),"",IF($F7=0,0,CR7/$F7)) -> 1 | CT7: 55 | CU7: =IF(OR($G7="",CT7=""),"",IF($G7=0,0,CT7/$G7)) -> 1 | CW7: =IF(OR($F7="",CV7=""),"",IF($F7=0,0,CV7/$F7)) | CY7: =IF(OR($G7="",CX7=""),"",IF($G7=0,0,CX7/$G7)) | DA7: =IF(OR($F7="",CZ7=""),"",IF($F7=0,0,CZ7/$F7)) | DC7: =IF(OR($G7="",DB7=""),"",IF($G7=0,0,DB7/$G7)) | DD7: 10 | DE7: =IF(OR($F7="",DD7=""),"",IF($F7=0,0,DD7/$F7)) -> 1 | DF7: 55 | DG7: =IF(OR($G7="",DF7=""),"",IF($G7=0,0,DF7/$G7)) -> 1 | DH7: 10 | DI7: =IF(OR($F7="",DH7=""),"",IF($F7=0,0,DH7/$F7)) -> 1 | DJ7: 55 | DK7: =IF(OR($G7="",DJ7=""),"",IF($G7=0,0,DJ7/$G7)) -> 1 | DL7: 10 | DM7: =IF(OR($F7="",DL7=""),"",IF($F7=0,0,DL7/$F7)) -> 1 | DN7: 55 | DO7: =IF(OR($G7="",DN7=""),"",IF($G7=0,0,DN7/$G7)) -> 1 | DP7: 10 | DQ7: =IF(OR($F7="",DP7=""),"",IF($F7=0,0,DP7/$F7)) -> 1 | DR7: 55 | DS7: =IF(OR($G7="",DR7=""),"",IF($G7=0,0,DR7/$G7)) -> 1 | DT7: 10 | DU7: =IF(OR($F7="",DT7=""),"",IF($F7=0,0,DT7/$F7)) -> 1 | DV7: 55 | DW7: =IF(OR($G7="",DV7=""),"",IF($G7=0,0,DV7/$G7)) -> 1 | DX7: 10 | DY7: =IF(OR($F7="",DX7=""),"",IF($F7=0,0,DX7/$F7)) -> 1 | DZ7: 55 | EA7: =IF(OR($G7="",DZ7=""),"",IF($G7=0,0,DZ7/$G7)) -> 1 | EB7: 10 | EC7: =IF(OR($F7="",EB7=""),"",IF($F7=0,0,EB7/$F7)) -> 1 | ED7: 55 | EE7: =IF(OR($G7="",ED7=""),"",IF($G7=0,0,ED7/$G7)) -> 1 | EF7: 10 | EG7: =IF(OR($F7="",EF7=""),"",IF($F7=0,0,EF7/$F7)) -> 1 | EH7: 55 | EI7: =IF(OR($G7="",EH7=""),"",IF($G7=0,0,EH7/$G7)) -> 1 | EJ7: 10 | EK7: =IF(OR($F7="",EJ7=""),"",IF($F7=0,0,EJ7/$F7)) -> 1 | EL7: 55 | EM7: =IF(OR($G7="",EL7=""),"",IF($G7=0,0,EL7/$G7)) -> 1 | EN7: 10 | EO7: =IF(OR($F7="",EN7=""),"",IF($F7=0,0,EN7/$F7)) -> 1 | EP7: 55 | EQ7: =IF(OR($G7="",EP7=""),"",IF($G7=0,0,EP7/$G7)) -> 1 | ER7: 10 | ES7: =IF(OR($F7="",ER7=""),"",IF($F7=0,0,ER7/$F7)) -> 1 | ET7: 55 | EU7: =IF(OR($G7="",ET7=""),"",IF($G7=0,0,ET7/$G7)) -> 1 | EV7: 10 | EW7: =IF(OR($F7="",EV7=""),"",IF($F7=0,0,EV7/$F7)) -> 1 | EX7: 55 | EY7: =IF(OR($G7="",EX7=""),"",IF($G7=0,0,EX7/$G7)) -> 1 | EZ7: 10 | FA7: =IF(OR($F7="",EZ7=""),"",IF($F7=0,0,EZ7/$F7)) -> 1 | FB7: 55 | FC7: =IF(OR($G7="",FB7=""),"",IF($G7=0,0,FB7/$G7)) -> 1 | FD7: 10 | FE7: =IF(OR($F7="",FD7=""),"",IF($F7=0,0,FD7/$F7)) -> 1 | FF7: 55 | FG7: =IF(OR($G7="",FF7=""),"",IF($G7=0,0,FF7/$G7)) -> 1 | FH7: 10 | FI7: =IF(OR($F7="",FH7=""),"",IF($F7=0,0,FH7/$F7)) -> 1 | FJ7: 55 | FK7: =IF(OR($G7="",FJ7=""),"",IF($G7=0,0,FJ7/$G7)) -> 1 | FL7: 10 | FM7: =IF(OR($F7="",FL7=""),"",IF($F7=0,0,FL7/$F7)) -> 1 | FO7: =IF(OR($G7="",FN7=""),"",IF($G7=0,0,FN7/$G7)) | FQ7: =IF(OR($F7="",FP7=""),"",IF($F7=0,0,FP7/$F7)) | FS7: =IF(OR($G7="",FR7=""),"",IF($G7=0,0,FR7/$G7)) | FU7: =IF(OR($F7="",FT7=""),"",IF($F7=0,0,FT7/$F7)) | FW7: =IF(OR($G7="",FV7=""),"",IF($G7=0,0,FV7/$G7)) | FY7: =IF(OR($F7="",FX7=""),"",IF($F7=0,0,FX7/$F7)) | GA7: =IF(OR($G7="",FZ7=""),"",IF($G7=0,0,FZ7/$G7)) | GC7: =IF(OR($F7="",GB7=""),"",IF($F7=0,0,GB7/$F7)) | GE7: =IF(OR($G7="",GD7=""),"",IF($G7=0,0,GD7/$G7)) | GG7: =IF(OR($F7="",GF7=""),"",IF($F7=0,0,GF7/$F7)) | GI7: =IF(OR($G7="",GH7=""),"",IF($G7=0,0,GH7/$G7)) | GK7: =IF(OR($F7="",GJ7=""),"",IF($F7=0,0,GJ7/$F7)) | GM7: =IF(OR($G7="",GL7=""),"",IF($G7=0,0,GL7/$G7)) | GO7: =IF(OR($F7="",GN7=""),"",IF($F7=0,0,GN7/$F7)) | GQ7: =IF(OR($G7="",GP7=""),"",IF($G7=0,0,GP7/$G7)) | GS7: =IF(OR($F7="",GR7=""),"",IF($F7=0,0,GR7/$F7)) | GU7: =IF(OR($G7="",GT7=""),"",IF($G7=0,0,GT7/$G7)) | GW7: =IF(OR($F7="",GV7=""),"",IF($F7=0,0,GV7/$F7)) | GY7: =IF(OR($G7="",GX7=""),"",IF($G7=0,0,GX7/$G7)) | HA7: =IF(OR($F7="",GZ7=""),"",IF($F7=0,0,GZ7/$F7)) | HC7: =IF(OR($G7="",HB7=""),"",IF($G7=0,0,HB7/$G7)) | HE7: =IF(OR($F7="",HD7=""),"",IF($F7=0,0,HD7/$F7)) | HG7: =IF(OR($G7="",HF7=""),"",IF($G7=0,0,HF7/$G7)) | HI7: =IF(OR($F7="",HH7=""),"",IF($F7=0,0,HH7/$F7)) | HK7: =IF(OR($G7="",HJ7=""),"",IF($G7=0,0,HJ7/$G7)) | HM7: =IF(OR($F7="",HL7=""),"",IF($F7=0,0,HL7/$F7)) | HO7: =IF(OR($G7="",HN7=""),"",IF($G7=0,0,HN7/$G7)) | HQ7: =IF(OR($F7="",HP7=""),"",IF($F7=0,0,HP7/$F7)) | HS7: =IF(OR($G7="",HR7=""),"",IF($G7=0,0,HR7/$G7)) | HU7: =IF(OR($F7="",HT7=""),"",IF($F7=0,0,HT7/$F7)) | HW7: =IF(OR($G7="",HV7=""),"",IF($G7=0,0,HV7/$G7)) | HY7: =IF(OR($F7="",HX7=""),"",IF($F7=0,0,HX7/$F7)) | IA7: =IF(OR($G7="",HZ7=""),"",IF($G7=0,0,HZ7/$G7)) | IC7: =IF(OR($F7="",IB7=""),"",IF($F7=0,0,IB7/$F7)) | IE7: =IF(OR($G7="",ID7=""),"",IF($G7=0,0,ID7/$G7)) | IG7: =IF(OR($F7="",IF7=""),"",IF($F7=0,0,IF7/$F7)) | II7: =IF(OR($G7="",IH7=""),"",IF($G7=0,0,IH7/$G7)) | IK7: =IF(OR($F7="",IJ7=""),"",IF($F7=0,0,IJ7/$F7)) | IM7: =IF(OR($G7="",IL7=""),"",IF($G7=0,0,IL7/$G7)) | IO7: =IF(OR($F7="",IN7=""),"",IF($F7=0,0,IN7/$F7)) | IQ7: =IF(OR($G7="",IP7=""),"",IF($G7=0,0,IP7/$G7)) | IS7: =IF(OR($F7="",IR7=""),"",IF($F7=0,0,IR7/$F7)) | IU7: =IF(OR($G7="",IT7=""),"",IF($G7=0,0,IT7/$G7)) | IW7: =IF(OR($F7="",IV7=""),"",IF($F7=0,0,IV7/$F7)) | IY7: =IF(OR($G7="",IX7=""),"",IF($G7=0,0,IX7/$G7)) | JA7: =IF(OR($F7="",IZ7=""),"",IF($F7=0,0,IZ7/$F7)) | JC7: =IF(OR($G7="",JB7=""),"",IF($G7=0,0,JB7/$G7)) | JE7: =IF(OR($F7="",JD7=""),"",IF($F7=0,0,JD7/$F7)) | JG7: =IF(OR($G7="",JF7=""),"",IF($G7=0,0,JF7/$G7)) | JI7: =IF(OR($F7="",JH7=""),"",IF($F7=0,0,JH7/$F7)) | JK7: =IF(OR($G7="",JJ7=""),"",IF($G7=0,0,JJ7/$G7)) | JM7: =IF(OR($F7="",JL7=""),"",IF($F7=0,0,JL7/$F7)) | JO7: =IF(OR($G7="",JN7=""),"",IF($G7=0,0,JN7/$G7)) | JQ7: =IF(OR($F7="",JP7=""),"",IF($F7=0,0,JP7/$F7)) | JS7: =IF(OR($G7="",JR7=""),"",IF($G7=0,0,JR7/$G7)) | JU7: =IF(OR($F7="",JT7=""),"",IF($F7=0,0,JT7/$F7)) | JW7: =IF(OR($G7="",JV7=""),"",IF($G7=0,0,JV7/$G7)) | JY7: =IF(OR($F7="",JX7=""),"",IF($F7=0,0,JX7/$F7)) | KA7: =IF(OR($G7="",JZ7=""),"",IF($G7=0,0,JZ7/$G7)) | KC7: =IF(OR($F7="",KB7=""),"",IF($F7=0,0,KB7/$F7)) | KE7: =IF(OR($G7="",KD7=""),"",IF($G7=0,0,KD7/$G7)) | KG7: =IF(OR($F7="",KF7=""),"",IF($F7=0,0,KF7/$F7)) | KI7: =IF(OR($G7="",KH7=""),"",IF($G7=0,0,KH7/$G7)) | KK7: =IF(OR($F7="",KJ7=""),"",IF($F7=0,0,KJ7/$F7)) | KM7: =IF(OR($G7="",KL7=""),"",IF($G7=0,0,KL7/$G7)) | KO7: =IF(OR($F7="",KN7=""),"",IF($F7=0,0,KN7/$F7)) | KQ7: =IF(OR($G7="",KP7=""),"",IF($G7=0,0,KP7/$G7)) | KS7: =IF(OR($F7="",KR7=""),"",IF($F7=0,0,KR7/$F7)) | KU7: =IF(OR($G7="",KT7=""),"",IF($G7=0,0,KT7/$G7)) | KW7: =IF(OR($F7="",KV7=""),"",IF($F7=0,0,KV7/$F7)) | KY7: =IF(OR($G7="",KX7=""),"",IF($G7=0,0,KX7/$G7)) | LA7: =IF(OR($F7="",KZ7=""),"",IF($F7=0,0,KZ7/$F7)) | LC7: =IF(OR($G7="",LB7=""),"",IF($G7=0,0,LB7/$G7)) | LE7: =IF(OR($F7="",LD7=""),"",IF($F7=0,0,LD7/$F7)) | LG7: =IF(OR($G7="",LF7=""),"",IF($G7=0,0,LF7/$G7)) | LI7: =IF(OR($F7="",LH7=""),"",IF($F7=0,0,LH7/$F7)) | LK7: =IF(OR($G7="",LJ7=""),"",IF($G7=0,0,LJ7/$G7)) | LM7: =IF(OR($F7="",LL7=""),"",IF($F7=0,0,LL7/$F7)) | LO7: =IF(OR($G7="",LN7=""),"",IF($G7=0,0,LN7/$G7)) | LQ7: =IF(OR($F7="",LP7=""),"",IF($F7=0,0,LP7/$F7)) | LS7: =IF(OR($G7="",LR7=""),"",IF($G7=0,0,LR7/$G7)) | LU7: =IF(OR($F7="",LT7=""),"",IF($F7=0,0,LT7/$F7)) | LW7: =IF(OR($G7="",LV7=""),"",IF($G7=0,0,LV7/$G7)) | LY7: =IF(OR($F7="",LX7=""),"",IF($F7=0,0,LX7/$F7)) | MA7: =IF(OR($G7="",LZ7=""),"",IF($G7=0,0,LZ7/$G7)) | MC7: =IF(OR($F7="",MB7=""),"",IF($F7=0,0,MB7/$F7)) | ME7: =IF(OR($G7="",MD7=""),"",IF($G7=0,0,MD7/$G7)) | MG7: =IF(OR($F7="",MF7=""),"",IF($F7=0,0,MF7/$F7)) | MI7: =IF(OR($G7="",MH7=""),"",IF($G7=0,0,MH7/$G7)) | MK7: =IF(OR($F7="",MJ7=""),"",IF($F7=0,0,MJ7/$F7)) | MM7: =IF(OR($G7="",ML7=""),"",IF($G7=0,0,ML7/$G7)) | MO7: =IF(OR($F7="",MN7=""),"",IF($F7=0,0,MN7/$F7)) | MQ7: =IF(OR($G7="",MP7=""),"",IF($G7=0,0,MP7/$G7)) | MS7: =IF(OR($F7="",MR7=""),"",IF($F7=0,0,MR7/$F7)) | MU7: =IF(OR($G7="",MT7=""),"",IF($G7=0,0,MT7/$G7)) | MW7: =IF(OR($F7="",MV7=""),"",IF($F7=0,0,MV7/$F7)) | MY7: =IF(OR($G7="",MX7=""),"",IF($G7=0,0,MX7/$G7)) | NA7: =IF(OR($F7="",MZ7=""),"",IF($F7=0,0,MZ7/$F7)) | NC7: =IF(OR($G7="",NB7=""),"",IF($G7=0,0,NB7/$G7)) | NE7: =IF(OR($F7="",ND7=""),"",IF($F7=0,0,ND7/$F7)) | NG7: =IF(OR($G7="",NF7=""),"",IF($G7=0,0,NF7/$G7)) | NI7: =IF(OR($F7="",NH7=""),"",IF($F7=0,0,NH7/$F7)) | NK7: =IF(OR($G7="",NJ7=""),"",IF($G7=0,0,NJ7/$G7)) | NM7: =IF(OR($F7="",NL7=""),"",IF($F7=0,0,NL7/$F7)) | NO7: =IF(OR($G7="",NN7=""),"",IF($G7=0,0,NN7/$G7)) | NQ7: =IF(OR($F7="",NP7=""),"",IF($F7=0,0,NP7/$F7)) | NS7: =IF(OR($G7="",NR7=""),"",IF($G7=0,0,NR7/$G7)) | NU7: =IF(OR($F7="",NT7=""),"",IF($F7=0,0,NT7/$F7)) | NW7: =IF(OR($G7="",NV7=""),"",IF($G7=0,0,NV7/$G7))
